Workbook

Sheet 바닥판
A1: 소재 | B1: 유형 | C1: 형태 | D1: 용도 | E1: 경계 | F1: 욕실폭 | G1: 욕실길이 | H1: 세면부폭 | I1: 세면부길이 | J1: 샤워부폭 | K1: 샤워부길이 | L1: 세면부바닥판 단가 | M1: 샤워부바닥판 단가 | N1: 소계
A2: GRP | B2: 기본형 | C2: 코너형 | D2: 샤워형 | E2: 구분 | F2: 1300 | G2: 1900 | H2: 1300 | I2: 1300 | J2: 850 | K2: 600 | L2: =바닥판단가!G2 -> 51610 | M2: =바닥판단가!G15 -> 20666 | N2: =바닥판단가!G2 + 바닥판단가!G15 -> 72276
A3: GRP | B3: 기본형 | C3: 코너형 | D3: 샤워형 | E3: 구분 | F3: 1300 | G3: 1900 | H3: 1300 | I3: 1300 | J3: 900 | K3: 600 | L3: =바닥판단가!G2 -> 51610 | M3: =바닥판단가!G16 -> 21190 | N3: =바닥판단가!G2 + 바닥판단가!G16 -> 72800
A4: GRP | B4: 기본형 | C4: 코너형 | D4: 샤워형 | E4: 구분 | F4: 1300 | G4: 2000 | H4: 1300 | I4: 1300 | J4: 900 | K4: 700 | L4: =바닥판단가!G2 -> 51610 | M4: =바닥판단가!G17 -> 22342 | N4: =바닥판단가!G2 + 바닥판단가!G17 -> 73952
A5: GRP | B5: 기본형 | C5: 코너형 | D5: 샤워형 | E5: 구분 | F5: 1300 | G5: 2000 | H5: 1300 | I5: 1400 | J5: 850 | K5: 600 | L5: =바닥판단가!G3 -> 53600 | M5: =바닥판단가!G15 -> 20666 | N5: =바닥판단가!G3 + 바닥판단가!G15 -> 74266
A6: GRP | B6: 기본형 | C6: 코너형 | D6: 샤워형 | E6: 구분 | F6: 1300 | G6: 2000 | H6: 1300 | I6: 1400 | J6: 900 | K6: 600 | L6: =바닥판단가!G3 -> 53600 | M6: =바닥판단가!G16 -> 21190 | N6: =바닥판단가!G3 + 바닥판단가!G16 -> 74790
A7: GRP | B7: 기본형 | C7: 코너형 | D7: 샤워형 | E7: 구분 | F7: 1300 | G7: 2100 | H7: 1300 | I7: 1300 | J7: 900 | K7: 800 | L7: =바닥판단가!G2 -> 51610 | M7: =바닥판단가!G18 -> 23494 | N7: =바닥판단가!G2 + 바닥판단가!G18 -> 75104
A8: GRP | B8: 기본형 | C8: 코너형 | D8: 샤워형 | E8: 구분 | F8: 1300 | G8: 2100 | H8: 1300 | I8: 1400 | J8: 900 | K8: 700 | L8: =바닥판단가!G3 -> 53600 | M8: =바닥판단가!G17 -> 22342 | N8: =바닥판단가!G3 + 바닥판단가!G17 -> 75942
A9: GRP | B9: 기본형 | C9: 코너형 | D9: 샤워형 | E9: 구분 | F9: 1300 | G9: 2100 | H9: 1300 | I9: 1500 | J9: 850 | K9: 600 | L9: =바닥판단가!G4 -> 55485 | M9: =바닥판단가!G15 -> 20666 | N9: =바닥판단가!G4 + 바닥판단가!G15 -> 76151
A10: GRP | B10: 기본형 | C10: 코너형 | D10: 샤워형 | E10: 구분 | F10: 1300 | G10: 2100 | H10: 1300 | I10: 1500 | J10: 900 | K10: 600 | L10: =바닥판단가!G4 -> 55485 | M10: =바닥판단가!G16 -> 21190 | N10: =바닥판단가!G4 + 바닥판단가!G16 -> 76675
A11: GRP | B11: 기본형 | C11: 코너형 | D11: 샤워형 | E11: 구분 | F11: 1300 | G11: 2200 | H11: 1300 | I11: 1300 | J11: 900 | K11: 900 | L11: =바닥판단가!G2 -> 51610 | M11: =바닥판단가!G19 -> 25066 | N11: =바닥판단가!G2 + 바닥판단가!G19 -> 76676
A12: GRP | B12: 기본형 | C12: 코너형 | D12: 샤워형 | E12: 구분 | F12: 1300 | G12: 2200 | H12: 1300 | I12: 1300 | J12: 1000 | K12: 900 | L12: =바닥판단가!G2 -> 51610 | M12: =바닥판단가!G21 -> 27161 | N12: =바닥판단가!G2 + 바닥판단가!G21 -> 78771
A13: GRP | B13: 기본형 | C13: 코너형 | D13: 샤워형 | E13: 구분 | F13: 1300 | G13: 2200 | H13: 1300 | I13: 1400 | J13: 900 | K13: 800 | L13: =바닥판단가!G3 -> 53600 | M13: =바닥판단가!G18 -> 23494 | N13: =바닥판단가!G3 + 바닥판단가!G18 -> 77094
A14: GRP | B14: 기본형 | C14: 코너형 | D14: 샤워형 | E14: 구분 | F14: 1300 | G14: 2200 | H14: 1300 | I14: 1500 | J14: 900 | K14: 700 | L14: =바닥판단가!G4 -> 55485 | M14: =바닥판단가!G17 -> 22342 | N14: =바닥판단가!G4 + 바닥판단가!G17 -> 77827
A15: GRP | B15: 기본형 | C15: 코너형 | D15: 샤워형 | E15: 구분 | F15: 1300 | G15: 2200 | H15: 1300 | I15: 1600 | J15: 850 | K15: 600 | L15: =바닥판단가!G5 -> 57790 | M15: =바닥판단가!G15 -> 20666 | N15: =바닥판단가!G5 + 바닥판단가!G15 -> 78456
A16: GRP | B16: 기본형 | C16: 코너형 | D16: 샤워형 | E16: 구분 | F16: 1300 | G16: 2200 | H16: 1300 | I16: 1600 | J16: 900 | K16: 600 | L16: =바닥판단가!G5 -> 57790 | M16: =바닥판단가!G16 -> 21190 | N16: =바닥판단가!G5 + 바닥판단가!G16 -> 78980
A17: GRP | B17: 기본형 | C17: 코너형 | D17: 샤워형 | E17: 구분 | F17: 1300 | G17: 2300 | H17: 1300 | I17: 1300 | J17: 1000 | K17: 1000 | L17: =바닥판단가!G2 -> 51610 | M17: =바닥판단가!G22 -> 29256 | N17: =바닥판단가!G2 + 바닥판단가!G22 -> 80866
A18: GRP | B18: 기본형 | C18: 코너형 | D18: 샤워형 | E18: 구분 | F18: 1300 | G18: 2300 | H18: 1300 | I18: 1400 | J18: 900 | K18: 900 | L18: =바닥판단가!G3 -> 53600 | M18: =바닥판단가!G19 -> 25066 | N18: =바닥판단가!G3 + 바닥판단가!G19 -> 78666
A19: GRP | B19: 기본형 | C19: 코너형 | D19: 샤워형 | E19: 구분 | F19: 1300 | G19: 2300 | H19: 1300 | I19: 1400 | J19: 1000 | K19: 900 | L19: =바닥판단가!G3 -> 53600 | M19: =바닥판단가!G21 -> 27161 | N19: =바닥판단가!G3 + 바닥판단가!G21 -> 80761
A20: GRP | B20: 기본형 | C20: 코너형 | D20: 샤워형 | E20: 구분 | F20: 1300 | G20: 2300 | H20: 1300 | I20: 1500 | J20: 900 | K20: 800 | L20: =바닥판단가!G4 -> 55485 | M20: =바닥판단가!G18 -> 23494 | N20: =바닥판단가!G4 + 바닥판단가!G18 -> 78979
A21: GRP | B21: 기본형 | C21: 코너형 | D21: 샤워형 | E21: 구분 | F21: 1300 | G21: 2300 | H21: 1300 | I21: 1600 | J21: 900 | K21: 700 | L21: =바닥판단가!G5 -> 57790 | M21: =바닥판단가!G17 -> 22342 | N21: =바닥판단가!G5 + 바닥판단가!G17 -> 80132
A22: GRP | B22: 기본형 | C22: 코너형 | D22: 샤워형 | E22: 구분 | F22: 1300 | G22: 2400 | H22: 1300 | I22: 1400 | J22: 1000 | K22: 1000 | L22: =바닥판단가!G3 -> 53600 | M22: =바닥판단가!G22 -> 29256 | N22: =바닥판단가!G3 + 바닥판단가!G22 -> 82856
A23: GRP | B23: 기본형 | C23: 코너형 | D23: 샤워형 | E23: 구분 | F23: 1300 | G23: 2400 | H23: 1300 | I23: 1500 | J23: 900 | K23: 900 | L23: =바닥판단가!G4 -> 55485 | M23: =바닥판단가!G19 -> 25066 | N23: =바닥판단가!G4 + 바닥판단가!G19 -> 80551
A24: GRP | B24: 기본형 | C24: 코너형 | D24: 샤워형 | E24: 구분 | F24: 1300 | G24: 2400 | H24: 1300 | I24: 1500 | J24: 1000 | K24: 900 | L24: =바닥판단가!G4 -> 55485 | M24: =바닥판단가!G21 -> 27161 | N24: =바닥판단가!G4 + 바닥판단가!G21 -> 82646
A25: GRP | B25: 기본형 | C25: 코너형 | D25: 샤워형 | E25: 구분 | F25: 1300 | G25: 2400 | H25: 1300 | I25: 1600 | J25: 900 | K25: 800 | L25: =바닥판단가!G5 -> 57790 | M25: =바닥판단가!G18 -> 23494 | N25: =바닥판단가!G5 + 바닥판단가!G18 -> 81284
A26: GRP | B26: 기본형 | C26: 코너형 | D26: 샤워형 | E26: 구분 | F26: 1300 | G26: 2500 | H26: 1300 | I26: 1500 | J26: 1000 | K26: 1000 | L26: =바닥판단가!G4 -> 55485 | M26: =바닥판단가!G22 -> 29256 | N26: =바닥판단가!G4 + 바닥판단가!G22 -> 84741
A27: GRP | B27: 기본형 | C27: 코너형 | D27: 샤워형 | E27: 구분 | F27: 1300 | G27: 2500 | H27: 1300 | I27: 1600 | J27: 900 | K27: 900 | L27: =바닥판단가!G5 -> 57790 | M27: =바닥판단가!G19 -> 25066 | N27: =바닥판단가!G5 + 바닥판단가!G19 -> 82856
A28: GRP | B28: 기본형 | C28: 코너형 | D28: 샤워형 | E28: 구분 | F28: 1300 | G28: 2500 | H28: 1300 | I28: 1600 | J28: 1000 | K28: 900 | L28: =바닥판단가!G5 -> 57790 | M28: =바닥판단가!G21 -> 27161 | N28: =바닥판단가!G5 + 바닥판단가!G21 -> 84951
A29: GRP | B29: 기본형 | C29: 코너형 | D29: 샤워형 | E29: 구분 | F29: 1400 | G29: 1900 | H29: 1400 | I29: 1300 | J29: 850 | K29: 600 | L29: =바닥판단가!G6 -> 53600 | M29: =바닥판단가!G15 -> 20666 | N29: =바닥판단가!G6 + 바닥판단가!G15 -> 74266
A30: GRP | B30: 기본형 | C30: 코너형 | D30: 샤워형 | E30: 구분 | F30: 1400 | G30: 1900 | H30: 1400 | I30: 1300 | J30: 900 | K30: 600 | L30: =바닥판단가!G6 -> 53600 | M30: =바닥판단가!G16 -> 21190 | N30: =바닥판단가!G6 + 바닥판단가!G16 -> 74790
A31: GRP | B31: 기본형 | C31: 코너형 | D31: 샤워형 | E31: 구분 | F31: 1400 | G31: 2000 | H31: 1400 | I31: 1300 | J31: 900 | K31: 700 | L31: =바닥판단가!G6 -> 53600 | M31: =바닥판단가!G17 -> 22342 | N31: =바닥판단가!G6 + 바닥판단가!G17 -> 75942
A32: GRP | B32: 기본형 | C32: 코너형 | D32: 샤워형 | E32: 구분 | F32: 1400 | G32: 2000 | H32: 1400 | I32: 1400 | J32: 850 | K32: 600 | L32: =바닥판단가!G7 -> 55695 | M32: =바닥판단가!G15 -> 20666 | N32: =바닥판단가!G7 + 바닥판단가!G15 -> 76361
A33: GRP | B33: 기본형 | C33: 코너형 | D33: 샤워형 | E33: 구분 | F33: 1400 | G33: 2000 | H33: 1400 | I33: 1400 | J33: 900 | K33: 600 | L33: =바닥판단가!G7 -> 55695 | M33: =바닥판단가!G16 -> 21190 | N33: =바닥판단가!G7 + 바닥판단가!G16 -> 76885
A34: GRP | B34: 기본형 | C34: 코너형 | D34: 샤워형 | E34: 구분 | F34: 1400 | G34: 2100 | H34: 1400 | I34: 1300 | J34: 900 | K34: 800 | L34: =바닥판단가!G6 -> 53600 | M34: =바닥판단가!G18 -> 23494 | N34: =바닥판단가!G6 + 바닥판단가!G18 -> 77094
A35: GRP | B35: 기본형 | C35: 코너형 | D35: 샤워형 | E35: 구분 | F35: 1400 | G35: 2100 | H35: 1400 | I35: 1400 | J35: 900 | K35: 700 | L35: =바닥판단가!G7 -> 55695 | M35: =바닥판단가!G17 -> 22342 | N35: =바닥판단가!G7 + 바닥판단가!G17 -> 78037
A36: GRP | B36: 기본형 | C36: 코너형 | D36: 샤워형 | E36: 구분 | F36: 1400 | G36: 2100 | H36: 1400 | I36: 1500 | J36: 850 | K36: 600 | L36: =바닥판단가!G8 -> 57581 | M36: =바닥판단가!G15 -> 20666 | N36: =바닥판단가!G8 + 바닥판단가!G15 -> 78247
A37: GRP | B37: 기본형 | C37: 코너형 | D37: 샤워형 | E37: 구분 | F37: 1400 | G37: 2100 | H37: 1400 | I37: 1500 | J37: 900 | K37: 600 | L37: =바닥판단가!G8 -> 57581 | M37: =바닥판단가!G16 -> 21190 | N37: =바닥판단가!G8 + 바닥판단가!G16 -> 78771
A38: GRP | B38: 기본형 | C38: 코너형 | D38: 샤워형 | E38: 구분 | F38: 1400 | G38: 2200 | H38: 1400 | I38: 1300 | J38: 900 | K38: 900 | L38: =바닥판단가!G6 -> 53600 | M38: =바닥판단가!G19 -> 25066 | N38: =바닥판단가!G6 + 바닥판단가!G19 -> 78666
A39: GRP | B39: 기본형 | C39: 코너형 | D39: 샤워형 | E39: 구분 | F39: 1400 | G39: 2200 | H39: 1400 | I39: 1300 | J39: 1000 | K39: 900 | L39: =바닥판단가!G6 -> 53600 | M39: =바닥판단가!G21 -> 27161 | N39: =바닥판단가!G6 + 바닥판단가!G21 -> 80761
A40: GRP | B40: 기본형 | C40: 코너형 | D40: 샤워형 | E40: 구분 | F40: 1400 | G40: 2200 | H40: 1400 | I40: 1400 | J40: 900 | K40: 800 | L40: =바닥판단가!G7 -> 55695 | M40: =바닥판단가!G18 -> 23494 | N40: =바닥판단가!G7 + 바닥판단가!G18 -> 79189
...

Sheet 바닥판단가
A1: 소재 | B1: 구조 | C1: 형태 | D1: 욕실공간 | E1: 폭 | F1: 길이 | G1: 단가 | H1: 비고
A2: GRP | B2: 기본형 | C2: 코너형 | D2: 세면부 | E2: 1300 | F2: 1300 | G2: 51610 | H2: 251106업데이트
A3: GRP | B3: 기본형 | C3: 코너형 | D3: 세면부 | E3: 1300 | F3: 1400 | G3: 53600
A4: GRP | B4: 기본형 | C4: 코너형 | D4: 세면부 | E4: 1300 | F4: 1500 | G4: 55485
A5: GRP | B5: 기본형 | C5: 코너형 | D5: 세면부 | E5: 1300 | F5: 1600 | G5: 57790
A6: GRP | B6: 기본형 | C6: 코너형 | D6: 세면부 | E6: 1400 | F6: 1300 | G6: 53600
A7: GRP | B7: 기본형 | C7: 코너형 | D7: 세면부 | E7: 1400 | F7: 1400 | G7: 55695
A8: GRP | B8: 기본형 | C8: 코너형 | D8: 세면부 | E8: 1400 | F8: 1500 | G8: 57581
A9: GRP | B9: 기본형 | C9: 코너형 | D9: 세면부 | E9: 1400 | F9: 1600 | G9: 59676
A10: GRP | B10: 기본형 | C10: 코너형 | D10: 세면부 | E10: 1500 | F10: 1300 | G10: 55485
A11: GRP | B11: 기본형 | C11: 코너형 | D11: 세면부 | E11: 1500 | F11: 1400 | G11: 57581
A12: GRP | B12: 기본형 | C12: 코너형 | D12: 세면부 | E12: 1500 | F12: 1500 | G12: 59676
A13: GRP | B13: 기본형 | C13: 코너형 | D13: 세면부 | E13: 1500 | F13: 1600 | G13: 61771
A14: GRP | B14: 기본형 | C14: 코너형 | D14: 세면부 | E14: 1600 | F14: 1300 | G14: 57790
... A72: GRP | B72: 타일일체형 | C72: 사각형 | D72: 욕조형 | E72: 1500 | F72: 1900 | G72: 98698

Sheet 천장판
A1: 판넬/점검구 | B1: 품명 | C1: 폭 | D1: 길이 | E1: 소계
A2: 바디판넬 | B2: SI-2 | C2: 2000 | D2: 1300 | E2: =ROUND(24876.5284210526,0) -> 24877
A3: 바디판넬 | B3: SI-3 | C3: 1750 | D3: 1300 | E3: =ROUND(19466.644754386,0) -> 19467
A4: 바디판넬 | B4: SI-4 | C4: 1750 | D4: 1350 | E4: =ROUND(20465.029754386,0) -> 20465
A5: 바디판넬 | B5: SI-5 | C5: 1750 | D5: 1350 | E5: =ROUND(22778.035754386,0) -> 22778
A6: 바디판넬 | B6: SI-6 | C6: 1750 | D6: 1450 | E6: =ROUND(22090.7790877193,0) -> 22091
A7: 바디판넬 | B7: SI-7 | C7: 1750 | D7: 1000 | E7: =ROUND(22305.1613333333,0) -> 22305
A8: 바디판넬 | B8: SI-8 | C8: 1750 | D8: 1200 | E8: =ROUND(25853.7433333333,0) -> 25854
A9: 바디판넬 | B9: SI-9 | C9: 2000 | D9: 1200 | E9: =ROUND(31177.068,0) -> 31177
A10: 바디판넬 | B10: SI-10 | C10: 1850 | D10: 1370 | E10: =ROUND(22090.7790877193,0) -> 22091
A11: 바디판넬 | B11: SI-11 | C11: 1850 | D11: 1260 | E11: =ROUND(21026.4810877193,0) -> 21026
A12: 사이드판넬 | B12: 700 | C12: 1750 | D12: 700 | E12: =ROUND(14109.9616666667,0) -> 14110
A13: 사이드판넬 | B13: 800 | C13: 1750 | D13: 800 | E13: =ROUND(15953.6971111111,0) -> 15954
A14: 사이드판넬 | B14: 900a | C14: 1750 | D14: 900 | E14: =ROUND(18683.766,0) -> 18684
A15: 사이드판넬 | B15: 900b | C15: 960 | D15: 900 | E15: =ROUND(10785.7126666667,0) -> 10786
A16: 사이드판넬 | B16: 1000 | C16: 1750 | D16: 1000 | E16: =ROUND(19905.1613333333,0) -> 19905
A17: 사이드판넬 | B17: 1200 | C17: 1750 | D17: 1200 | E17: =ROUND(23453.7433333333,0) -> 23454
A18: 사이드판넬 | B18: 2000 | C18: 2000 | D18: 1200 | E18: =ROUND(28777.068,0) -> 28777
A19: 사이드판넬 | B19: 750 | C19: 1850 | D19: 750 | E19: =ROUND(14527.649,0) -> 14528
A20: 사이드판넬 | B20: 1100 | C20: 1850 | D20: 1100 | E20: =ROUND(20189.7306666667,0) -> 20190
A21: 점검구 | B21: SI-2 | C21: 900 | D21: 700 | E21: =ROUND(8585.984,0) -> 8586
A22: 점검구 | B22: SI-3 | C22: 900 | D22: 700 | E22: =ROUND(8585.984,0) -> 8586
A23: 점검구 | B23: SI-4 | C23: 900 | D23: 700 | E23: =ROUND(8585.984,0) -> 8586
A24: 점검구 | B24: SI-5 | C24: 650 | D24: 500 | E24: =ROUND(6296.838,0) -> 6297
A25: 점검구 | B25: SI-6 | C25: 900 | D25: 700 | E25: =ROUND(8585.984,0) -> 8586
A26: 점검구 | B26: SI-7 | C26: 450 | D26: 450 | E26: =ROUND(4728.38884210526,0) -> 4728
A27: 점검구 | B27: SI-8 | C27: 450 | D27: 450 | E27: =ROUND(4728.38884210526,0) -> 4728
A28: 점검구 | B28: SI-9 | C28: 450 | D28: 450 | E28: =ROUND(4728.38884210526,0) -> 4728
A29: 점검구 | B29: SI-10 | C29: 900 | D29: 650 | E29: =ROUND(8174.96333333333,0) -> 8175
A30: 점검구 | B30: SI-11 | C30: 900 | D30: 750 | E30: =ROUND(8184.748,0) -> 8185

Sheet 천장판타공
A1: 품목 | B1: 단가 | C1: 비고
A2: 바디 | B2: 30000 | C2: 2인 40EA/시간(1면절단)
A3: 사이드 | B3: 30500 | C3: 2인 40EA/시간(1면절단)
A4: 환풍기홀 | B4: 4000 | C4: 2인 15EA/시간(1개)
A5: 사각매립등 | B5: 4000 | C5: 2인 15EA/시간(1개)
A6: 원형등 | B6: 2000 | C6: 2인 35EA/시간(1개)
A7: 직선1회 | B7: 1500 | C7: 2인 40EA/시간

Sheet 자동지정항목
A1: 대분류 | B1: 중분류 | C1: 사양 및 규격
A2: 욕실타일벽체 세트 | B2: 사각형(샤워타입) | C2: 1400*1900LA
A3: 욕실타일벽체 세트 | B3: 사각형(샤워타입) | C3: 1400*1900RA
A4: 욕실타일벽체 세트 | B4: 코너신형 | C4: 1500*2300LA
A5: 욕실타일벽체 세트 | B5: 코너신형 | C5: 1500*2300RA
A6: 욕실타일벽체 세트 | B6: 코너신형 | C6: 1500*2300LA(주약)
A7: 욕실타일벽체 세트 | B7: 코너신형 | C7: 1500*2300RA(주약)
A8: 욕실타일벽체 세트 | B8: 코너형
A9: 욕실타일벽체 세트 | B9: 코너형
A10: 오배수배관 | B10: PVC파이프(VG2) | C10: 100A
A11: 오배수배관 | B11: PVC파이프(VG2) | C11: 65A
A12: 오배수배관 | B12: PVC파이프(VG1) | C12: 50A
A13: 오배수배관 | B13: 양변기 엘보 | C13: 100A
A14: 오배수배관 | B14: 저소음 엘보 | C14: 50A
A15: 오배수배관 | B15: 임시마개(양변기용) | C15: 100A
A16: 오배수배관 | B16: PVC본드 | C16: 1KG
A17: 냉온수배관 | B17: PB독립배관
A18: 냉온수배관 | B18: PB이중관(오픈수전함)
A19: 타일류 | B19: 벽체용 타일 300*600
A20: 타일류 | B20: 벽체용 타일 250*400
A21: 타일류 | B21: 바닥용 타일 300*300
A22: 타일류 | B22: 바닥용 타일 200*200
A23: 타일류 | B23: DWL1769 | C23: 250*400
A24: 타일류 | B24: DWL2903 | C24: 250*400
A25: 타일류 | B25: HBD4063 | C25: 200*200
A26: 타일류 | B26: HBD7063 | C26: 200*200
A27: 문세트(일반) | B27: 문틀(일반) | C27: 710*2120(130바)
A28: 문세트(일반) | B28: 문짝(일반) | C28: 642*2052
A29: 문세트(일반) | B29: 문짝(포켓도어)
A30: 문세트(일반) | B30: 도어락
A31: 문세트(일반) | B31: 경첩(스텐피스)
A32: 문세트(일반) | B32: 스토퍼
A33: 문세트(포켓도어) | B33: 가틀(포켓도어)
A34: 문세트(포켓도어) | B34: 본틀(포켓도어)
A35: 문세트(포켓도어) | B35: 문틀 받침대
A36: 문세트(포켓도어) | B36: 오목손잡이
A37: 도기 및 수전 | B37: 양변기
A38: 도기 및 수전 | B38: 세면기
A39: 도기 및 수전 | B39: 세면기 수전
A40: 도기 및 수전 | B40: 겸용 수전
...

Sheet 자재단가내역
A1: 대분류 | B1: 중분류 | C1: 사양 및 규격 | D1: 단가
A2: 욕실타일벽체 세트 | B2: 코너형 | C2: 1700*2200LA | D2: 1500
A3: 욕실타일벽체 세트 | B3: 코너신형 | C3: 1500*2300LA | D3: 2000
A4: 욕실타일벽체 세트 | B4: 코너신형 | C4: 1500*2300LA(주약) | D4: 3150 | H4: 규칙
A5: 욕실타일벽체 세트 | B5: 코너신형 | C5: 1600*2100LA | D5: 500 | H5: 대분류/중분류/사양 및 규격이 정확히 일치하는 품목을 추가했을 때 견적서 생성에 반영됨
A6: 욕실타일벽체 세트 | B6: 코너신형 | C6: 1600*2100LA(주약) | D6: 1000
A7: 욕실타일벽체 세트 | B7: 코너신형 | C7: 1600*2200LA | D7: 4000
A8: 욕실타일벽체 세트 | B8: 코너신형 | C8: 1600*2200LA(주약) | D8: 999
A9: 욕실타일벽체 세트 | B9: 코너신형 | C9: 1700*2200LA | D9: 999
A10: 욕실타일벽체 세트 | B10: 사각형(샤워타입) | C10: 1400*1900LA | D10: 999
A11: 욕실타일벽체 세트 | B11: 사각형(샤워타입) | C11: 1400*1900RA | D11: 3950
A12: 욕실타일벽체 세트 | B12: 사각형(샤워타입) | C12: 1500*2200LA | D12: 4600
A13: 욕조 SL | B13: SL1600*3.5 | C13: 750*1600 | D13: 35000
A14: 욕조 SL | B14: SL1750*3.5 | C14: 750*1750 | D14: 15000
A15: 욕조 | B15: 욕조 시공비 | C15: NONE | D15: 999
A16: 욕조 SL | B16: SL욕조 기초판 | C16: 400*1065*50 | D16: 6000
A17: 욕조 SP | B17: SP1400*3.5 | C17: 720*1400 | D17: 999
... A24: 에프런 SP | B24: SP1700 | C24: 510*1700 | D24: 2380
A25: FRP바닥판 | B25: 사각형(사워타입) | D25: 15000
A26: FRP바닥판 | B26: 사각형(사워타입) | D26: 570
A27: FRP바닥판 | B27: 사각형(사워타입) | D27: 1000
A28: FRP바닥판 | B28: 사각형(사워타입) | D28: 800
A29: 욕실천장판 | B29: 1000 사이드 | C29: 1000*1750 | D29: 3000
A30: 욕실천장판 | B30: 1100 사이드 | C30: 1100*1850 | D30: 5500
A31: 욕실천장판 | B31: 1200 사이드 | C31: 1200*1750 | D31: 6000
A32: 욕실천장판 | B32: SI-185 바디 | C32: 1370*1850 | D32: 2000
A33: 욕실천장판 | B33: SI-185 돔형 점검구 | C33: 650*900 | D33: 30000
A34: 욕실천장판 | B34: SI-185 평형 점검구 | C34: 650*900 | D34: =18000/15 -> 1200
A35: 욕실천장판 | B35: 무광-1 바디 | C35: 1370*1750 | D35: =18000/9 -> 2000
A36: 욕실천장판 | B36: 무광-1 바디 | C36: 1370*1750 | D36: 6000
A37: 욕실천장판 | B37: SI-1 돔형 점검구 | C37: 750*900 | D37: 100000
A38: 욕실천장판 | B38: 2000 사이드 | C38: 1200*2000 | D38: 85000
A39: 욕실천장판 | B39: SI-2,3,4,5 돔형 점검구 | C39: 700*900 | D39: 75000
A40: 욕실천장판 | B40: SI-2,3,4,5 평형 점검구 | C40: 700*900 | D40: =15000/37 -> 405.40541
A41: 욕실천장판 | B41: SI-2 바디 | C41: 1300*2000 | D41: =15000/16 -> 937.5
A42: 욕실천장판 | B42: SI-3 바디 | C42: 1300*1750 | D42: 999
A43: 욕실천장판 | B43: SI-4 바디 | C43: 1350*1750 | D43: 999
A44: 욕실천장판 | B44: SI-5 바디 | C44: 1450*1750 | D44: 999
A45: 욕실천장판 | B45: SI-6,7,8 평형 점검구 | C45: 450*450 | D45: 999
A46: 욕실천장판 | B46: SI-6 바디 | C46: 1000*1750 | D46: 12000
...

Sheet 벽판
A1: variable | B1: value
A2: 프레임단가_15각 | B2: 1440
A3: 프레임단가_16각 | B3: 1485
A4: 프레임단가_19각 | B4: 1798
A5: P_U단가_15각 | B5: 3162
A6: P_U단가_16각 | B6: 3341
A7: P_U단가_19각 | B7: 3930
A8: 조립클립단가 | B8: 4320
A9: 설비감가비 | B9: 830
A10: 제조경비_판넬당 | B10: 434.60925
A11: 타일관리비_단가 | B11: 60
A12: 출고_렉입고_단가 | B12: 3730
A13: 생산인건비_일단가 | B13: 269000
... A23: 도어폭_0_8m | B23: 0.8

Sheet PVE
A1: PVE 욕실 유형 | B1: 원재료비 | C1: 가공비
A2: 일반형 | B2: 12000 | C2: 24331
A3: 욕실선반형 | B3: 12000 | C3: 31159

Sheet 데이터 설명
A1: 바닥판 단가
A2: 컬럼 | B2: 타입 | C2: 단위 | D2: 예시 | E2: 설명
A3: 소재 | B3: string | C3: - | D3: GRP | E3: 바닥판 소재 구분(GRP/FRP). PVE는 GRP/FRP가 아닌 경우에 선택하게 됨
A4: 구조 | B4: string | C4: - | D4: 기본형 | E4: 제품 구조/배수/일체형 구분
A5: 형태 | B5: string | C5: - | D5: 코너형 | E5: 욕실 형태(코너/사각/욕조 등)
A6: 욕실공간 | B6: string | C6: - | D6: 세면부 | E6: 적용 구간(세면/샤워/단차없음/샤워형/욕조형 등)
A7: 폭 | B7: int | C7: mm | D7: 1300 | E7: 바닥판 폭(가로)
A8: 길이 | B8: int | C8: mm | D8: 1500 | E8: 바닥판 길이(세로)
A9: 단가 | B9: int | C9: KRW | D9: 51610 | E9: 단가(원). 쉼표/공백 제거 후 정수로 저장 권장
A11: 바닥판
A12: 컬럼 | B12: 타입 | C12: 단위 | D12: 허용값/예시 | E12: 설명
A13: 소재 | B13: string | C13: - | D13: GRP, FRP | E13: 바닥판 소재
A14: 유형 | B14: string | C14: - | D14: 기본형, 중앙배수, 일체형, 타일일체형 | E14: 구조/제품 타입
A15: 형태 | B15: string | C15: - | D15: 코너형, 사각형 | E15: 욕실 형태
A16: 용도 | B16: string | C16: - | D16: 샤워형, 욕조형 | E16: 욕실 용도 구분
A17: 경계 | B17: string | C17: - | D17: 구분, 구분없음 | E17: 세면/샤워 분해 여부
A18: 욕실폭 | B18: int | C18: mm | D18: 1300 | E18: 전체 욕실 폭
A19: 욕실길이 | B19: int | C19: mm | D19: 1900 | E19: 전체 욕실 길이
A20: 세면부폭 | B20: int/NaN | C20: mm | D20: 1300 또는 NaN | E20: 경계=구분일 때만 채움
A21: 세면부길이 | B21: int/NaN | C21: mm | D21: 1400 또는 NaN | E21: 경계=구분일 때만 채움
A22: 샤워부폭 | B22: int/NaN | C22: mm | D22: 900 또는 NaN | E22: 경계=구분일 때만 채움
A23: 샤워부길이 | B23: int/NaN | C23: mm | D23: 700 또는 NaN | E23: 경계=구분일 때만 채움
A24: 세면부바닥판 단가 | B24: int/NaN | C24: KRW | D24: 51610 또는 NaN | E24: 세면부 바닥판 단가(원)
A25: 샤워부바닥판 단가 | B25: int/NaN | C25: KRW | D25: 20666 또는 NaN | E25: 샤워부 바닥판 단가(원)
A26: 소계 | B26: int | C26: KRW | D26: 72276 | E26: 최종 합계 단가(원)
A28: 천장판
A29: 컬럼명 | B29: 타입 | C29: 단위 | D29: 예시 | E29: 설명
A30: 판넬/점검구 | B30: string | C30: - | D30: 바디판넬 | E30: 품목(카테고리) 구분(바디판넬/사이드판넬/점검구)
A31: 품명 | B31: string | C31: - | D31: SI-2 | E31: 카탈로그 품번/규격 코드(예: SI-2, 900a, 1100 등)
A32: 폭 | B32: int | C32: mm | D32: 2000 | E32: 폭(가로) 치수
A33: 길이 | B33: int | C33: mm | D33: 1300 | E33: 길이(세로) 치수
A34: 소계 | B34: int | C34: KRW | D34: 24877 | E34: 품목 1개 기준 단가(원). 쉼표/공백이 있으면 제거 후 정수 변환 권장
A36: 벽판
A37: 컬럼명 | B37: 타입 | C37: 단위 | D37: 예시 | E37: 설명
A38: variable | B38: string | C38: - | D38: 프레임단가_15각 | E38: 상수 이름(키). 코드에서 이 문자열로 값을 조회함
A39: value | B39: number | C39: (변수별 상이) | D39: 1440 | E39: 상수 값. 단위는 변수 의미에 따라 다르며, 가능하면 별도 unit 컬럼 추가 권장
A40: 자동지정항목 / 자재단가 내역
A41: 대분류/중분류/사양 및 규격이 정확히 일치하는 품목을 추가했을 때 견적서 생성에 반영됨
A42: 자동지정항목 시트와 자재단가 내역의 대분류/중분류/사양 및 규격이 일치해야 탐지 가능
